bash: cannot set terminal process group (339742): Inappropriate ioctl for device
bash: no job control in this shell
Traceback (most recent call last):
  File "/home/arelius/anaconda3/envs/tmp/lib/python3.8/site-packages/oauth2client/clientsecrets.py", line 121, in _loadfile
    with open(filename, 'r') as fp:
FileNotFoundError: [Errno 2] No such file or directory: 'client_secret.json'

During handling of the above exception, another exception occurred:

Traceback (most recent call last):
  File "/home/arelius/anaconda3/envs/tmp/lib/python3.8/site-packages/simplegmail/gmail.py", line 87, in __init__
    flow = client.flow_from_clientsecrets(
  File "/home/arelius/anaconda3/envs/tmp/lib/python3.8/site-packages/oauth2client/_helpers.py", line 133, in positional_wrapper
    return wrapped(*args, **kwargs)
  File "/home/arelius/anaconda3/envs/tmp/lib/python3.8/site-packages/oauth2client/client.py", line 2134, in flow_from_clientsecrets
    client_type, client_info = clientsecrets.loadfile(filename,
  File "/home/arelius/anaconda3/envs/tmp/lib/python3.8/site-packages/oauth2client/clientsecrets.py", line 165, in loadfile
    return _loadfile(filename)
  File "/home/arelius/anaconda3/envs/tmp/lib/python3.8/site-packages/oauth2client/clientsecrets.py", line 124, in _loadfile
    raise InvalidClientSecretsError('Error opening file', exc.filename,
oauth2client.clientsecrets.InvalidClientSecretsError: ('Error opening file', 'client_secret.json', 'No such file or directory', 2)

During handling of the above exception, another exception occurred:

Traceback (most recent call last):
  File "/home/arelius/workspace/joplin-server/daily-email.py", line 59, in <module>
    mailman.send_email(subject=f"Yesterday Progress | {percent}% | {frac}", body=html)
  File "/home/arelius/workspace/joplin-server/mailman.py", line 6, in send_email
    gmail = Gmail() # will open a browser window to ask you to log in and authenticate
  File "/home/arelius/anaconda3/envs/tmp/lib/python3.8/site-packages/simplegmail/gmail.py", line 107, in __init__
    raise FileNotFoundError(
FileNotFoundError: Your 'client_secret.json' file is nonexistent. Make sure the file is in the root directory of your application. If you don't have a client secrets file, go to https://developers.google.com/gmail/api/quickstart/python, and follow the instructions listed there.
